*** Starting uWSGI 2.0.18 (64bit) on [Sun Apr 28 13:32:49 2019] ***
compiled with version: 6.3.0 20170516 on 27 April 2019 15:54:53
os: Linux-4.9.125-linuxkit #1 SMP Fri Sep 7 08:20:28 UTC 2018
nodename: 0449ddba6ad0
machine: x86_64
clock source: unix
pcre jit disabled
detected number of CPU cores: 4
current working directory: /code
detected binary path: /usr/local/bin/uwsgi
uWSGI running as root, you can use --uid/--gid/--chroot options
*** WARNING: you are running uWSGI as root !!! (use the --uid flag) *** 
*** WARNING: you are running uWSGI without its master process manager ***
your memory page size is 4096 bytes
detected max file descriptor number: 1048576
lock engine: pthread robust mutexes
thunder lock: disabled (you can enable it with --thunder-lock)
uwsgi socket 0 bound to TCP address :8001 fd 3
uWSGI running as root, you can use --uid/--gid/--chroot options
*** WARNING: you are running uWSGI as root !!! (use the --uid flag) *** 
Python version: 3.7.3 (default, Mar 27 2019, 23:40:30)  [GCC 6.3.0 20170516]
*** Python threads support is disabled. You can enable it with --enable-threads ***
Python main interpreter initialized at 0x55f404db8d50
uWSGI running as root, you can use --uid/--gid/--chroot options
*** WARNING: you are running uWSGI as root !!! (use the --uid flag) *** 
your server socket listen backlog is limited to 100 connections
your mercy for graceful operations on workers is 60 seconds
mapped 72920 bytes (71 KB) for 1 cores
*** Operational MODE: single process ***
WSGI app 0 (mountpoint='') ready in 1 seconds on interpreter 0x55f404db8d50 pid: 1 (default app)
mountpoint  already configured. skip.
uWSGI running as root, you can use --uid/--gid/--chroot options
*** WARNING: you are running uWSGI as root !!! (use the --uid flag) *** 
*** uWSGI is running in multiple interpreter mode ***
spawned uWSGI worker 1 (and the only) (pid: 1, cores: 1)
Internal Server Error: /
Traceback (most recent call last):
  File "/usr/local/lib/python3.7/site-packages/django/core/handlers/exception.py", line 34, in inner
    response = get_response(request)
  File "/usr/local/lib/python3.7/site-packages/django/core/handlers/base.py", line 126, in _get_response
    response = self.process_exception_by_middleware(e, request)
  File "/usr/local/lib/python3.7/site-packages/django/core/handlers/base.py", line 124, in _get_response
    response = wrapped_callback(request, *callback_args, **callback_kwargs)
  File "./blog/views.py", line 4, in post_list
    return render(request, 'blog/post_list.html', {})
  File "/usr/local/lib/python3.7/site-packages/django/shortcuts.py", line 36, in render
    content = loader.render_to_string(template_name, context, request, using=using)
  File "/usr/local/lib/python3.7/site-packages/django/template/loader.py", line 61, in render_to_string
    template = get_template(template_name, using=using)
  File "/usr/local/lib/python3.7/site-packages/django/template/loader.py", line 19, in get_template
    raise TemplateDoesNotExist(template_name, chain=chain)
django.template.exceptions.TemplateDoesNotExist: blog/post_list.html
[pid: 1|app: 0|req: 1/1] 192.168.32.1 () {44 vars in 1765 bytes} [Sun Apr 28 22:32:55 2019] GET / => generated 73571 bytes in 130 msecs (HTTP/1.1 500) 4 headers in 129 bytes (1 switches on core 0)
Internal Server Error: /
Traceback (most recent call last):
  File "/usr/local/lib/python3.7/site-packages/django/core/handlers/exception.py", line 34, in inner
    response = get_response(request)
  File "/usr/local/lib/python3.7/site-packages/django/core/handlers/base.py", line 126, in _get_response
    response = self.process_exception_by_middleware(e, request)
  File "/usr/local/lib/python3.7/site-packages/django/core/handlers/base.py", line 124, in _get_response
    response = wrapped_callback(request, *callback_args, **callback_kwargs)
  File "./blog/views.py", line 4, in post_list
    return render(request, 'blog/post_list.html', {})
  File "/usr/local/lib/python3.7/site-packages/django/shortcuts.py", line 36, in render
    content = loader.render_to_string(template_name, context, request, using=using)
  File "/usr/local/lib/python3.7/site-packages/django/template/loader.py", line 61, in render_to_string
    template = get_template(template_name, using=using)
  File "/usr/local/lib/python3.7/site-packages/django/template/loader.py", line 19, in get_template
    raise TemplateDoesNotExist(template_name, chain=chain)
django.template.exceptions.TemplateDoesNotExist: blog/post_list.html
[pid: 1|app: 0|req: 2/2] 192.168.32.1 () {44 vars in 1765 bytes} [Sun Apr 28 22:32:55 2019] GET / => generated 73571 bytes in 52 msecs (HTTP/1.1 500) 4 headers in 129 bytes (1 switches on core 0)
Internal Server Error: /
Traceback (most recent call last):
  File "/usr/local/lib/python3.7/site-packages/django/core/handlers/exception.py", line 34, in inner
    response = get_response(request)
  File "/usr/local/lib/python3.7/site-packages/django/core/handlers/base.py", line 126, in _get_response
    response = self.process_exception_by_middleware(e, request)
  File "/usr/local/lib/python3.7/site-packages/django/core/handlers/base.py", line 124, in _get_response
    response = wrapped_callback(request, *callback_args, **callback_kwargs)
  File "./blog/views.py", line 4, in post_list
    return render(request, 'blog/post_list.html', {})
  File "/usr/local/lib/python3.7/site-packages/django/shortcuts.py", line 36, in render
    content = loader.render_to_string(template_name, context, request, using=using)
  File "/usr/local/lib/python3.7/site-packages/django/template/loader.py", line 61, in render_to_string
    template = get_template(template_name, using=using)
  File "/usr/local/lib/python3.7/site-packages/django/template/loader.py", line 19, in get_template
    raise TemplateDoesNotExist(template_name, chain=chain)
django.template.exceptions.TemplateDoesNotExist: blog/post_list.html
[pid: 1|app: 0|req: 3/3] 192.168.32.1 () {44 vars in 1765 bytes} [Sun Apr 28 22:32:56 2019] GET / => generated 73571 bytes in 64 msecs (HTTP/1.1 500) 4 headers in 129 bytes (1 switches on core 0)
Internal Server Error: /
Traceback (most recent call last):
  File "/usr/local/lib/python3.7/site-packages/django/core/handlers/exception.py", line 34, in inner
    response = get_response(request)
  File "/usr/local/lib/python3.7/site-packages/django/core/handlers/base.py", line 126, in _get_response
    response = self.process_exception_by_middleware(e, request)
  File "/usr/local/lib/python3.7/site-packages/django/core/handlers/base.py", line 124, in _get_response
    response = wrapped_callback(request, *callback_args, **callback_kwargs)
  File "./blog/views.py", line 4, in post_list
    return render(request, 'blog/post_list.html', {})
  File "/usr/local/lib/python3.7/site-packages/django/shortcuts.py", line 36, in render
    content = loader.render_to_string(template_name, context, request, using=using)
  File "/usr/local/lib/python3.7/site-packages/django/template/loader.py", line 61, in render_to_string
    template = get_template(template_name, using=using)
  File "/usr/local/lib/python3.7/site-packages/django/template/loader.py", line 19, in get_template
    raise TemplateDoesNotExist(template_name, chain=chain)
django.template.exceptions.TemplateDoesNotExist: blog/post_list.html
[pid: 1|app: 0|req: 4/4] 192.168.32.1 () {44 vars in 1765 bytes} [Sun Apr 28 22:32:57 2019] GET / => generated 73571 bytes in 51 msecs (HTTP/1.1 500) 4 headers in 129 bytes (1 switches on core 0)
Internal Server Error: /
Traceback (most recent call last):
  File "/usr/local/lib/python3.7/site-packages/django/core/handlers/exception.py", line 34, in inner
    response = get_response(request)
  File "/usr/local/lib/python3.7/site-packages/django/core/handlers/base.py", line 126, in _get_response
    response = self.process_exception_by_middleware(e, request)
  File "/usr/local/lib/python3.7/site-packages/django/core/handlers/base.py", line 124, in _get_response
    response = wrapped_callback(request, *callback_args, **callback_kwargs)
  File "./blog/views.py", line 4, in post_list
    return render(request, 'blog/post_list.html', {})
  File "/usr/local/lib/python3.7/site-packages/django/shortcuts.py", line 36, in render
    content = loader.render_to_string(template_name, context, request, using=using)
  File "/usr/local/lib/python3.7/site-packages/django/template/loader.py", line 61, in render_to_string
    template = get_template(template_name, using=using)
  File "/usr/local/lib/python3.7/site-packages/django/template/loader.py", line 19, in get_template
    raise TemplateDoesNotExist(template_name, chain=chain)
django.template.exceptions.TemplateDoesNotExist: blog/post_list.html
[pid: 1|app: 0|req: 5/5] 192.168.32.1 () {46 vars in 1787 bytes} [Sun Apr 28 22:33:01 2019] GET / => generated 73697 bytes in 52 msecs (HTTP/1.1 500) 4 headers in 129 bytes (1 switches on core 0)
Not Found: /favicon.ico
[pid: 1|app: 0|req: 6/6] 192.168.32.1 () {46 vars in 1733 bytes} [Sun Apr 28 22:33:01 2019] GET /favicon.ico => generated 2137 bytes in 6 msecs (HTTP/1.1 404) 3 headers in 102 bytes (1 switches on core 0)
Internal Server Error: /
Traceback (most recent call last):
  File "/usr/local/lib/python3.7/site-packages/django/core/handlers/exception.py", line 34, in inner
    response = get_response(request)
  File "/usr/local/lib/python3.7/site-packages/django/core/handlers/base.py", line 126, in _get_response
    response = self.process_exception_by_middleware(e, request)
  File "/usr/local/lib/python3.7/site-packages/django/core/handlers/base.py", line 124, in _get_response
    response = wrapped_callback(request, *callback_args, **callback_kwargs)
  File "./blog/views.py", line 4, in post_list
    return render(request, 'blog/post_list.html', {})
  File "/usr/local/lib/python3.7/site-packages/django/shortcuts.py", line 36, in render
    content = loader.render_to_string(template_name, context, request, using=using)
  File "/usr/local/lib/python3.7/site-packages/django/template/loader.py", line 61, in render_to_string
    template = get_template(template_name, using=using)
  File "/usr/local/lib/python3.7/site-packages/django/template/loader.py", line 19, in get_template
    raise TemplateDoesNotExist(template_name, chain=chain)
django.template.exceptions.TemplateDoesNotExist: blog/post_list.html
[pid: 1|app: 0|req: 7/7] 192.168.32.1 () {42 vars in 857 bytes} [Sun Apr 28 22:33:45 2019] GET / => generated 70396 bytes in 80 msecs (HTTP/1.1 500) 4 headers in 129 bytes (1 switches on core 0)
Not Found: /favicon.ico
[pid: 1|app: 0|req: 8/8] 192.168.32.1 () {42 vars in 803 bytes} [Sun Apr 28 22:33:45 2019] GET /favicon.ico => generated 2137 bytes in 6 msecs (HTTP/1.1 404) 3 headers in 102 bytes (1 switches on core 0)
Internal Server Error: /
Traceback (most recent call last):
  File "/usr/local/lib/python3.7/site-packages/django/core/handlers/exception.py", line 34, in inner
    response = get_response(request)
  File "/usr/local/lib/python3.7/site-packages/django/core/handlers/base.py", line 126, in _get_response
    response = self.process_exception_by_middleware(e, request)
  File "/usr/local/lib/python3.7/site-packages/django/core/handlers/base.py", line 124, in _get_response
    response = wrapped_callback(request, *callback_args, **callback_kwargs)
  File "./blog/views.py", line 4, in post_list
    return render(request, 'blog/post_list.html', {})
  File "/usr/local/lib/python3.7/site-packages/django/shortcuts.py", line 36, in render
    content = loader.render_to_string(template_name, context, request, using=using)
  File "/usr/local/lib/python3.7/site-packages/django/template/loader.py", line 61, in render_to_string
    template = get_template(template_name, using=using)
  File "/usr/local/lib/python3.7/site-packages/django/template/loader.py", line 19, in get_template
    raise TemplateDoesNotExist(template_name, chain=chain)
django.template.exceptions.TemplateDoesNotExist: blog/post_list.html
[pid: 1|app: 0|req: 9/9] 192.168.32.1 () {42 vars in 1813 bytes} [Sun Apr 28 22:34:57 2019] GET / => generated 73951 bytes in 60 msecs (HTTP/1.1 500) 4 headers in 129 bytes (1 switches on core 0)
Internal Server Error: /
Traceback (most recent call last):
  File "/usr/local/lib/python3.7/site-packages/django/core/handlers/exception.py", line 34, in inner
    response = get_response(request)
  File "/usr/local/lib/python3.7/site-packages/django/core/handlers/base.py", line 126, in _get_response
    response = self.process_exception_by_middleware(e, request)
  File "/usr/local/lib/python3.7/site-packages/django/core/handlers/base.py", line 124, in _get_response
    response = wrapped_callback(request, *callback_args, **callback_kwargs)
  File "./blog/views.py", line 4, in post_list
    return render(request, 'blog/post_list.html', {})
  File "/usr/local/lib/python3.7/site-packages/django/shortcuts.py", line 36, in render
    content = loader.render_to_string(template_name, context, request, using=using)
  File "/usr/local/lib/python3.7/site-packages/django/template/loader.py", line 61, in render_to_string
    template = get_template(template_name, using=using)
  File "/usr/local/lib/python3.7/site-packages/django/template/loader.py", line 19, in get_template
    raise TemplateDoesNotExist(template_name, chain=chain)
django.template.exceptions.TemplateDoesNotExist: blog/post_list.html
[pid: 1|app: 0|req: 10/10] 192.168.32.1 () {46 vars in 1866 bytes} [Sun Apr 28 22:34:59 2019] GET / => generated 74212 bytes in 55 msecs (HTTP/1.1 500) 4 headers in 129 bytes (1 switches on core 0)
Not Found: /favicon.ico
[pid: 1|app: 0|req: 11/11] 192.168.32.1 () {46 vars in 1812 bytes} [Sun Apr 28 22:34:59 2019] GET /favicon.ico => generated 2137 bytes in 7 msecs (HTTP/1.1 404) 3 headers in 102 bytes (1 switches on core 0)
*** Starting uWSGI 2.0.18 (64bit) on [Sun Apr 28 13:40:52 2019] ***
compiled with version: 6.3.0 20170516 on 27 April 2019 15:54:53
os: Linux-4.9.125-linuxkit #1 SMP Fri Sep 7 08:20:28 UTC 2018
nodename: 33d10b72c388
machine: x86_64
clock source: unix
pcre jit disabled
detected number of CPU cores: 4
current working directory: /code
detected binary path: /usr/local/bin/uwsgi
uWSGI running as root, you can use --uid/--gid/--chroot options
*** WARNING: you are running uWSGI as root !!! (use the --uid flag) *** 
your memory page size is 4096 bytes
detected max file descriptor number: 1048576
lock engine: pthread robust mutexes
thunder lock: disabled (you can enable it with --thunder-lock)
uwsgi socket 0 bound to TCP address :8001 fd 3
uWSGI running as root, you can use --uid/--gid/--chroot options
*** WARNING: you are running uWSGI as root !!! (use the --uid flag) *** 
Python version: 3.7.3 (default, Mar 27 2019, 23:40:30)  [GCC 6.3.0 20170516]
Python main interpreter initialized at 0x56500a054d50
uWSGI running as root, you can use --uid/--gid/--chroot options
*** WARNING: you are running uWSGI as root !!! (use the --uid flag) *** 
python threads support enabled
your server socket listen backlog is limited to 100 connections
your mercy for graceful operations on workers is 60 seconds
mapped 145840 bytes (142 KB) for 1 cores
*** Operational MODE: single process ***
WSGI app 0 (mountpoint='') ready in 1 seconds on interpreter 0x56500a054d50 pid: 1 (default app)
mountpoint  already configured. skip.
uWSGI running as root, you can use --uid/--gid/--chroot options
*** WARNING: you are running uWSGI as root !!! (use the --uid flag) *** 
*** uWSGI is running in multiple interpreter mode ***
spawned uWSGI master process (pid: 1)
spawned uWSGI worker 1 (pid: 7, cores: 1)
Python auto-reloader enabled
[pid: 7|app: 0|req: 1/1] 192.168.48.1 () {44 vars in 1798 bytes} [Sun Apr 28 22:41:06 2019] GET / => generated 88 bytes in 47 msecs (HTTP/1.1 200) 3 headers in 108 bytes (1 switches on core 0)
[pid: 7|app: 0|req: 2/2] 192.168.48.1 () {44 vars in 1798 bytes} [Sun Apr 28 22:41:34 2019] GET / => generated 93 bytes in 7 msecs (HTTP/1.1 200) 3 headers in 108 bytes (1 switches on core 0)
...brutally killing workers...
worker 1 buried after 1 seconds
binary reloading uWSGI...
chdir() to /code
closing all non-uwsgi socket fds > 2 (max_fd = 1048576)...
found fd 3 mapped to socket 0 (:8001)
running /usr/local/bin/uwsgi
[uWSGI] getting INI configuration from /code/mysite/django.ini
*** Starting uWSGI 2.0.18 (64bit) on [Sun Apr 28 22:41:41 2019] ***
compiled with version: 6.3.0 20170516 on 27 April 2019 15:54:53
os: Linux-4.9.125-linuxkit #1 SMP Fri Sep 7 08:20:28 UTC 2018
nodename: 33d10b72c388
machine: x86_64
clock source: unix
pcre jit disabled
detected number of CPU cores: 4
current working directory: /code
detected binary path: /usr/local/bin/uwsgi
uWSGI running as root, you can use --uid/--gid/--chroot options
*** WARNING: you are running uWSGI as root !!! (use the --uid flag) *** 
your memory page size is 4096 bytes
detected max file descriptor number: 1048576
lock engine: pthread robust mutexes
thunder lock: disabled (you can enable it with --thunder-lock)
uwsgi socket 0 inherited INET address :8001 fd 3
uWSGI running as root, you can use --uid/--gid/--chroot options
*** WARNING: you are running uWSGI as root !!! (use the --uid flag) *** 
Python version: 3.7.3 (default, Mar 27 2019, 23:40:30)  [GCC 6.3.0 20170516]
Python main interpreter initialized at 0x563ea46d8de0
uWSGI running as root, you can use --uid/--gid/--chroot options
*** WARNING: you are running uWSGI as root !!! (use the --uid flag) *** 
python threads support enabled
your server socket listen backlog is limited to 100 connections
your mercy for graceful operations on workers is 60 seconds
mapped 145840 bytes (142 KB) for 1 cores
*** Operational MODE: single process ***
WSGI app 0 (mountpoint='') ready in 1 seconds on interpreter 0x563ea46d8de0 pid: 1 (default app)
mountpoint  already configured. skip.
uWSGI running as root, you can use --uid/--gid/--chroot options
*** WARNING: you are running uWSGI as root !!! (use the --uid flag) *** 
*** uWSGI is running in multiple interpreter mode ***
gracefully (RE)spawned uWSGI master process (pid: 1)
spawned uWSGI worker 1 (pid: 9, cores: 1)
Python auto-reloader enabled
*** Starting uWSGI 2.0.18 (64bit) on [Sun Apr 28 13:41:59 2019] ***
compiled with version: 6.3.0 20170516 on 27 April 2019 15:54:53
os: Linux-4.9.125-linuxkit #1 SMP Fri Sep 7 08:20:28 UTC 2018
nodename: 33d10b72c388
machine: x86_64
clock source: unix
pcre jit disabled
detected number of CPU cores: 4
current working directory: /code
detected binary path: /usr/local/bin/uwsgi
uWSGI running as root, you can use --uid/--gid/--chroot options
*** WARNING: you are running uWSGI as root !!! (use the --uid flag) *** 
your memory page size is 4096 bytes
detected max file descriptor number: 1048576
lock engine: pthread robust mutexes
thunder lock: disabled (you can enable it with --thunder-lock)
uwsgi socket 0 bound to TCP address :8001 fd 3
uWSGI running as root, you can use --uid/--gid/--chroot options
*** WARNING: you are running uWSGI as root !!! (use the --uid flag) *** 
Python version: 3.7.3 (default, Mar 27 2019, 23:40:30)  [GCC 6.3.0 20170516]
Python main interpreter initialized at 0x5603706e7d50
uWSGI running as root, you can use --uid/--gid/--chroot options
*** WARNING: you are running uWSGI as root !!! (use the --uid flag) *** 
python threads support enabled
your server socket listen backlog is limited to 100 connections
your mercy for graceful operations on workers is 60 seconds
mapped 145840 bytes (142 KB) for 1 cores
*** Operational MODE: single process ***
WSGI app 0 (mountpoint='') ready in 1 seconds on interpreter 0x5603706e7d50 pid: 1 (default app)
mountpoint  already configured. skip.
uWSGI running as root, you can use --uid/--gid/--chroot options
*** WARNING: you are running uWSGI as root !!! (use the --uid flag) *** 
*** uWSGI is running in multiple interpreter mode ***
spawned uWSGI master process (pid: 1)
spawned uWSGI worker 1 (pid: 6, cores: 1)
Python auto-reloader enabled
